[0m18:51:47.240980 [debug] [MainThread]: Sending event: {'category': 'dbt', 'action': 'invocation', 'label': 'start', 'context': [<snowplow_tracker.self_describing_json.SelfDescribingJson object at 0x7fb8ea8ec610>, <snowplow_tracker.self_describing_json.SelfDescribingJson object at 0x7fb8e99ece20>, <snowplow_tracker.self_describing_json.SelfDescribingJson object at 0x7fb8ea678730>]}


============================== 18:51:47.247029 | 9d42da62-4fe7-4801-b82a-c9720a86b9d8 ==============================
[0m18:51:47.247029 [info ] [MainThread]: Running with dbt=1.9.1
[0m18:51:47.248613 [debug] [MainThread]: running dbt with arguments {'printer_width': '80', 'indirect_selection': 'eager', 'write_json': 'True', 'log_cache_events': 'False', 'partial_parse': 'True', 'cache_selected_only': 'False', 'warn_error': 'None', 'debug': 'False', 'version_check': 'True', 'log_path': 'logs', 'fail_fast': 'False', 'profiles_dir': '/home/cloudshell-user/.dbt', 'use_colors': 'True', 'use_experimental_parser': 'False', 'no_print': 'None', 'quiet': 'False', 'empty': 'None', 'log_format': 'default', 'static_parser': 'True', 'invocation_command': 'dbt init dbt_project', 'warn_error_options': 'WarnErrorOptions(include=[], exclude=[])', 'target_path': 'None', 'introspect': 'True', 'send_anonymous_usage_stats': 'True'}
[0m18:51:47.265361 [warn ] [MainThread]: [ConfigFolderDirectory]: Unable to parse logging event dictionary. Failed to parse dir field: expected string or bytes-like object.. Dictionary: {'dir': PosixPath('/home/cloudshell-user/.dbt')}
[0m18:51:47.266709 [info ] [MainThread]: Creating dbt configuration folder at 
[0m18:51:47.269743 [debug] [MainThread]: Starter project path: /home/cloudshell-user/.local/lib/python3.9/site-packages/dbt/include/starter_project
[0m18:51:47.274050 [info ] [MainThread]: 
Your new dbt project "dbt_project" was created!

For more information on how to configure the profiles.yml file,
please consult the dbt documentation here:

  https://docs.getdbt.com/docs/configure-your-profile

One more thing:

Need help? Don't hesitate to reach out to us via GitHub issues or on Slack:

  https://community.getdbt.com/

Happy modeling!

[0m18:51:47.274833 [info ] [MainThread]: Setting up your profile.
[0m19:08:32.069133 [error] [MainThread]: Encountered an error:

[0m19:08:32.072179 [error] [MainThread]: Traceback (most recent call last):
  File "/home/cloudshell-user/.local/lib/python3.9/site-packages/dbt/cli/requires.py", line 153, in wrapper
    result, success = func(*args, **kwargs)
  File "/home/cloudshell-user/.local/lib/python3.9/site-packages/dbt/cli/requires.py", line 103, in wrapper
    return func(*args, **kwargs)
  File "/home/cloudshell-user/.local/lib/python3.9/site-packages/dbt/cli/main.py", line 477, in init
    results = task.run()
  File "/home/cloudshell-user/.local/lib/python3.9/site-packages/dbt/task/init.py", line 346, in run
    self.setup_profile(profile_name)
  File "/home/cloudshell-user/.local/lib/python3.9/site-packages/dbt/task/init.py", line 262, in setup_profile
    self.create_profile_from_target(adapter, profile_name=profile_name)
  File "/home/cloudshell-user/.local/lib/python3.9/site-packages/dbt/task/init.py", line 179, in create_profile_from_target
    self.create_profile_from_profile_template(profile_template, profile_name)
  File "/home/cloudshell-user/.local/lib/python3.9/site-packages/dbt/task/init.py", line 163, in create_profile_from_profile_template
    target = self.generate_target_from_input(prompts, initial_target)
  File "/home/cloudshell-user/.local/lib/python3.9/site-packages/dbt/task/init.py", line 129, in generate_target_from_input
    target[key] = click.prompt(
  File "/usr/local/lib/python3.9/site-packages/click/termui.py", line 164, in prompt
    value = prompt_func(prompt)
  File "/usr/local/lib/python3.9/site-packages/click/termui.py", line 147, in prompt_func
    raise Abort() from None
click.exceptions.Abort

[0m19:08:32.076529 [debug] [MainThread]: Resource report: {"command_name": "init", "command_success": false, "command_wall_clock_time": 1004.9919, "process_in_blocks": "168", "process_kernel_time": 0.125565, "process_mem_max_rss": "91988", "process_out_blocks": "72", "process_user_time": 1.749189}
[0m19:08:32.077559 [debug] [MainThread]: Command `dbt init` failed at 19:08:32.077388 after 1004.99 seconds
[0m19:08:32.078082 [debug] [MainThread]: Sending event: {'category': 'dbt', 'action': 'invocation', 'label': 'end', 'context': [<snowplow_tracker.self_describing_json.SelfDescribingJson object at 0x7fb8ea8ec610>, <snowplow_tracker.self_describing_json.SelfDescribingJson object at 0x7fb8e99ec670>, <snowplow_tracker.self_describing_json.SelfDescribingJson object at 0x7fb8e99ec1c0>]}
[0m19:08:32.078685 [debug] [MainThread]: Flushing usage events
[0m19:08:32.092907 [debug] [MainThread]: An error was encountered while trying to flush usage events
[0m23:34:25.731741 [debug] [MainThread]: Sending event: {'category': 'dbt', 'action': 'invocation', 'label': 'start', 'context': [<snowplow_tracker.self_describing_json.SelfDescribingJson object at 0x7f408bd10580>, <snowplow_tracker.self_describing_json.SelfDescribingJson object at 0x7f408ae142e0>, <snowplow_tracker.self_describing_json.SelfDescribingJson object at 0x7f408ae14280>]}


============================== 23:34:25.738968 | 3c8796c2-2ba7-4274-b224-6e42a6b40f1b ==============================
[0m23:34:25.738968 [info ] [MainThread]: Running with dbt=1.9.1
[0m23:34:25.740411 [debug] [MainThread]: running dbt with arguments {'printer_width': '80', 'indirect_selection': 'eager', 'log_cache_events': 'False', 'write_json': 'True', 'partial_parse': 'True', 'cache_selected_only': 'False', 'profiles_dir': '/home/cloudshell-user/.dbt', 'version_check': 'True', 'warn_error': 'None', 'log_path': 'logs', 'fail_fast': 'False', 'debug': 'False', 'use_colors': 'True', 'use_experimental_parser': 'False', 'no_print': 'None', 'quiet': 'False', 'empty': 'None', 'log_format': 'default', 'invocation_command': 'dbt docs generate', 'warn_error_options': 'WarnErrorOptions(include=[], exclude=[])', 'static_parser': 'True', 'target_path': 'None', 'introspect': 'True', 'send_anonymous_usage_stats': 'True'}
[0m23:34:25.741377 [error] [MainThread]: Encountered an error:
Runtime Error
  No dbt_project.yml found at expected path /home/cloudshell-user/car-data-project/dbt_project.yml
  Verify that each entry within packages.yml (and their transitive dependencies) contains a file named dbt_project.yml
  
[0m23:34:25.745070 [debug] [MainThread]: Resource report: {"command_name": "generate", "command_success": false, "command_wall_clock_time": 0.13339439, "process_in_blocks": "29456", "process_kernel_time": 0.176355, "process_mem_max_rss": "86896", "process_out_blocks": "8", "process_user_time": 1.709714}
[0m23:34:25.746287 [debug] [MainThread]: Command `dbt docs generate` failed at 23:34:25.746076 after 0.13 seconds
[0m23:34:25.747048 [debug] [MainThread]: Sending event: {'category': 'dbt', 'action': 'invocation', 'label': 'end', 'context': [<snowplow_tracker.self_describing_json.SelfDescribingJson object at 0x7f408bd10580>, <snowplow_tracker.self_describing_json.SelfDescribingJson object at 0x7f408ae14580>, <snowplow_tracker.self_describing_json.SelfDescribingJson object at 0x7f408ae14220>]}
[0m23:34:25.747811 [debug] [MainThread]: Flushing usage events
[0m23:34:25.777490 [debug] [MainThread]: An error was encountered while trying to flush usage events
[0m23:50:48.548385 [debug] [MainThread]: Sending event: {'category': 'dbt', 'action': 'invocation', 'label': 'start', 'context': [<snowplow_tracker.self_describing_json.SelfDescribingJson object at 0x7f49868ef5b0>, <snowplow_tracker.self_describing_json.SelfDescribingJson object at 0x7f49859f32e0>, <snowplow_tracker.self_describing_json.SelfDescribingJson object at 0x7f49859f3280>]}


============================== 23:50:48.554715 | fa57db18-f4e6-427e-94c9-00dd39e4ffcc ==============================
[0m23:50:48.554715 [info ] [MainThread]: Running with dbt=1.9.1
[0m23:50:48.556275 [debug] [MainThread]: running dbt with arguments {'printer_width': '80', 'indirect_selection': 'eager', 'log_cache_events': 'False', 'write_json': 'True', 'partial_parse': 'True', 'cache_selected_only': 'False', 'profiles_dir': '/home/cloudshell-user/.dbt', 'debug': 'False', 'version_check': 'True', 'log_path': 'logs', 'warn_error': 'None', 'fail_fast': 'False', 'use_colors': 'True', 'use_experimental_parser': 'False', 'no_print': 'None', 'quiet': 'False', 'empty': 'None', 'log_format': 'default', 'static_parser': 'True', 'invocation_command': 'dbt docs generate', 'introspect': 'True', 'target_path': 'None', 'warn_error_options': 'WarnErrorOptions(include=[], exclude=[])', 'send_anonymous_usage_stats': 'True'}
[0m23:50:48.559627 [error] [MainThread]: Encountered an error:
Runtime Error
  No dbt_project.yml found at expected path /home/cloudshell-user/car-data-project/dbt_project.yml
  Verify that each entry within packages.yml (and their transitive dependencies) contains a file named dbt_project.yml
  
[0m23:50:48.562234 [debug] [MainThread]: Resource report: {"command_name": "generate", "command_success": false, "command_wall_clock_time": 0.127835, "process_in_blocks": "0", "process_kernel_time": 0.123639, "process_mem_max_rss": "86844", "process_out_blocks": "16", "process_user_time": 1.734035}
[0m23:50:48.564076 [debug] [MainThread]: Command `dbt docs generate` failed at 23:50:48.563899 after 0.13 seconds
[0m23:50:48.565064 [debug] [MainThread]: Sending event: {'category': 'dbt', 'action': 'invocation', 'label': 'end', 'context': [<snowplow_tracker.self_describing_json.SelfDescribingJson object at 0x7f49868ef5b0>, <snowplow_tracker.self_describing_json.SelfDescribingJson object at 0x7f49859f3580>, <snowplow_tracker.self_describing_json.SelfDescribingJson object at 0x7f49859f3220>]}
[0m23:50:48.565708 [debug] [MainThread]: Flushing usage events
[0m23:50:48.599447 [debug] [MainThread]: An error was encountered while trying to flush usage events
[0m02:03:08.808067 [debug] [MainThread]: Sending event: {'category': 'dbt', 'action': 'invocation', 'label': 'start', 'context': [<snowplow_tracker.self_describing_json.SelfDescribingJson object at 0x7f4f4477c610>, <snowplow_tracker.self_describing_json.SelfDescribingJson object at 0x7f4f438c0940>, <snowplow_tracker.self_describing_json.SelfDescribingJson object at 0x7f4f438c08e0>]}


============================== 02:03:08.817465 | 25045080-24a4-4f88-a03b-d9202527c3eb ==============================
[0m02:03:08.817465 [info ] [MainThread]: Running with dbt=1.9.1
[0m02:03:08.819295 [debug] [MainThread]: running dbt with arguments {'printer_width': '80', 'indirect_selection': 'eager', 'write_json': 'True', 'log_cache_events': 'False', 'partial_parse': 'True', 'cache_selected_only': 'False', 'warn_error': 'None', 'version_check': 'True', 'profiles_dir': '/home/cloudshell-user/.dbt', 'log_path': 'logs', 'fail_fast': 'False', 'debug': 'False', 'use_colors': 'True', 'use_experimental_parser': 'False', 'no_print': 'None', 'quiet': 'False', 'empty': 'None', 'log_format': 'default', 'static_parser': 'True', 'warn_error_options': 'WarnErrorOptions(include=[], exclude=[])', 'invocation_command': 'dbt docs generate', 'target_path': 'None', 'introspect': 'True', 'send_anonymous_usage_stats': 'True'}
[0m02:03:08.820557 [error] [MainThread]: Encountered an error:
Runtime Error
  No dbt_project.yml found at expected path /home/cloudshell-user/car-data-project/dbt_project.yml
  Verify that each entry within packages.yml (and their transitive dependencies) contains a file named dbt_project.yml
  
[0m02:03:08.823768 [debug] [MainThread]: Resource report: {"command_name": "generate", "command_success": false, "command_wall_clock_time": 0.1434066, "process_in_blocks": "29728", "process_kernel_time": 0.148041, "process_mem_max_rss": "86808", "process_out_blocks": "8", "process_user_time": 2.33331}
[0m02:03:08.825099 [debug] [MainThread]: Command `dbt docs generate` failed at 02:03:08.824895 after 0.15 seconds
[0m02:03:08.825776 [debug] [MainThread]: Sending event: {'category': 'dbt', 'action': 'invocation', 'label': 'end', 'context': [<snowplow_tracker.self_describing_json.SelfDescribingJson object at 0x7f4f4477c610>, <snowplow_tracker.self_describing_json.SelfDescribingJson object at 0x7f4f438c0be0>, <snowplow_tracker.self_describing_json.SelfDescribingJson object at 0x7f4f438c0880>]}
[0m02:03:08.826743 [debug] [MainThread]: Flushing usage events
[0m02:03:08.846147 [debug] [MainThread]: An error was encountered while trying to flush usage events
